Warning: Log dir /Users/kiranganeshan/self-play/agent/data/ppo/ppo_s0 already exists! Storing info there anyway.
[32;1mLogging data to /Users/kiranganeshan/self-play/agent/data/ppo/ppo_s0/progress.txt[0m
/opt/anaconda3/envs/spinningup/lib/python3.6/site-packages/gym/logger.py:30: UserWarning: [33mWARN: Box bound precision lowered by casting to float32[0m
  warnings.warn(colorize('%s: %s'%('WARN', msg % args), 'yellow'))
[32;1m
Number of parameters: 	 pi: 10008, 	 v: 9281
[0m
Normal(loc: torch.Size([12]), scale: torch.Size([12]))
[-0.7580473  -1.2138528  -1.1745739  -1.1842824   0.3806191   0.5791315
  0.3409195   0.01457827 -0.18970421 -0.1299358  -0.23243505  0.45646334]
Traceback (most recent call last):
  File "ppo.py", line 446, in <module>
    task_name=args.task_name)
  File "ppo.py", line 313, in ppo
    next_o, r, d, _ = env.step(a)
  File "/opt/anaconda3/envs/spinningup/lib/python3.6/site-packages/gym/wrappers/time_limit.py", line 16, in step
    observation, reward, done, info = self.env.step(action)
  File "/opt/anaconda3/envs/spinningup/lib/python3.6/site-packages/dmc2gym/wrappers.py", line 141, in step
    assert self._norm_action_space.contains(action)
AssertionError
